#VRML_SIM R2023b utf8
# license: Apache License 2.0
# license url: http://www.apache.org/licenses/LICENSE-2.0
# This is a proto file for Webots for the excavator
# Extracted from: D:\Users\Muafi\Documents\NAUFAL MU'AFI\Universitas Gadjah Mada\Skripsi\VisuoExcaRobo\Excavator\excavator.urdf

PROTO excavator [
  field  SFVec3f     translation     0 0 0
  field  SFRotation  rotation        0 0 1 0
  field  SFString    name            "excavator"  # Is `Robot.name`.
  field  SFString    controller      "void"       # Is `Robot.controller`.
  field  MFString    controllerArgs  []           # Is `Robot.controllerArgs`.
  field  SFString    customData      ""           # Is `Robot.customData`.
  field  SFBool      supervisor      FALSE        # Is `Robot.supervisor`.
  field  SFBool      synchronization TRUE         # Is `Robot.synchronization`.
  field  SFBool      selfCollision   FALSE        # Is `Robot.selfCollision`.
]
{
  Robot {
    translation IS translation
    rotation IS rotation
    controller IS controller
    controllerArgs IS controllerArgs
    customData IS customData
    supervisor IS supervisor
    synchronization IS synchronization
    selfCollision IS selfCollision
    children [
      DEF base_link Solid {
        children [
          Shape {
            appearance PBRAppearance {
              baseColor 0.500000 0.500000 0.500000
              roughness 1.000000
              metalness 0
            }
            geometry DEF base_link Mesh {
              url "base_link.STL"
            }
          }
          DEF link2_to_base HingeJoint {
            jointParameters HingeJointParameters {
              axis 0.000000 0.000000 1.000000
              anchor -0.858500 -0.082500 1.466000
            }
            device [
              RotationalMotor {
                name "link2_to_base"
                maxVelocity 0.1
                minPosition -3.1
                maxPosition 3.1
                maxTorque 300.0
              }
              PositionSensor {
                name "link2_to_base_sensor"
              }
            ]
            endPoint DEF link2 Solid {
              translation -0.858500 -0.082500 1.466000
              rotation 0.000000 0.000000 1.000000 0.075368
              children [
                Shape {
                  appearance PBRAppearance {
                    baseColor 0.500000 0.500000 0.500000
                    roughness 1.000000
                    metalness 0
                  }
                  geometry DEF link2 Mesh {
                    url "link2.STL"
                  }
                }
                DEF link3_to_link2 HingeJoint {
                  jointParameters HingeJointParameters {
                    axis 0.075297 0.997161 -0.000000
                    anchor 1.306000 -0.015884 -0.544000
                  }
                  device [
                    RotationalMotor {
                      name "link3_to_link2"
                      maxVelocity 0.1
                      minPosition -0.954
                      maxPosition 1.03
                      maxTorque 300.0
                    }
                    PositionSensor {
                      name "link3_to_link2_sensor"
                    }
                  ]
                  endPoint DEF link3 Solid {
                    translation 1.306000 -0.015884 -0.544000
                    rotation 0.036815 0.976481 -0.212437 0.351289
                    children [
                      Shape {
                        appearance PBRAppearance {
                          baseColor 0.500000 0.500000 0.500000
                          roughness 1.000000
                          metalness 0
                        }
                        geometry DEF link3 Mesh {
                          url "link3.STL"
                        }
                      }
                      DEF link4_to_link3 HingeJoint {
                        jointParameters HingeJointParameters {
                          axis 0.000000 1.000000 0.000000
                          anchor 6.989100 0.000000 2.550600
                        }
                        device [
                          RotationalMotor {
                            name "link4_to_link3"
                            maxVelocity 0.1
                            minPosition -0.1214
                            maxPosition 1.51
                            maxTorque 300.0
                          }
                          PositionSensor {
                            name "link4_to_link3_sensor"
                          }
                        ]
                        endPoint DEF link4 Solid {
                          translation 6.989100 0.000000 2.550600
                          rotation 0.000000 1.000000 0.000000 0.406120
                          children [
                            Shape {
                              appearance PBRAppearance {
                                baseColor 0.500000 0.500000 0.500000
                                roughness 1.000000
                                metalness 0
                              }
                              geometry DEF link4 Mesh {
                                url "link4.STL"
                              }
                            }
                            DEF link5_to_link4 HingeJoint {
                              jointParameters HingeJointParameters {
                                axis 0.000000 1.000000 0.000000
                                anchor 2.604700 0.000000 0.785070
                              }
                              device [
                                RotationalMotor {
                                  name "link5_to_link4"
                                  maxVelocity 0.1
                                  minPosition -0.32
                                  maxPosition 3.14
                                  maxTorque 300.0
                                }
                                PositionSensor {
                                  name "link5_to_link4_sensor"
                                }
                              ]
                              endPoint DEF link5 Solid {
                                translation 2.604700 0.000000 0.785070
                                rotation 0.000000 -1.000000 0.000000 0.881310
                                children [
                                  Shape {
                                    appearance PBRAppearance {
                                      baseColor 0.500000 0.500000 0.500000
                                      roughness 1.000000
                                      metalness 0
                                    }
                                    geometry DEF link5 Mesh {
                                      url "link5.STL"
                                    }
                                  }
                                  DEF Link_EE Solid {
                                    translation 2.000000 0.000000 -0.750000
                                    children [
                                      Shape {
                                        appearance PBRAppearance {
                                          baseColor 0.500000 0.500000 0.500000
                                          roughness 1.000000
                                          metalness 0
                                        }
                                        geometry Sphere {
                                          radius 0.0001
                                        }
                                      }
                                    ]
                                    name "Link_EE"
                                    physics Physics {
                                      density -1
                                      mass 1.000000
                                      centerOfMass [ 0.000000 0.000000 0.000000 ]
                                    }
                                  }
                                ]
                                name "link5"
                                boundingObject USE link5
                                physics Physics {
                                  density -1
                                  mass 641.548893
                                  centerOfMass [ 1.006968 0.000001 0.422752 ]
                                  inertiaMatrix [
                                    4.831001e+02 4.503348e+02 6.395493e+02
                                    -3.147198e-04 7.853876e+01 3.199451e-04
                                  ]
                                }
                              }
                            }
                          ]
                          name "link4"
                          boundingObject USE link4
                          physics Physics {
                            density -1
                            mass 112.346086
                            centerOfMass [ 0.544768 0.000001 0.709714 ]
                            inertiaMatrix [
                              9.696159e+00 9.904282e+01 9.689206e+01
                              6.763330e-05 -1.637085e+00 -3.536930e-06
                            ]
                          }
                        }
                      }
                    ]
                    name "link3"
                    boundingObject USE link3
                    physics Physics {
                      density -1
                      mass 2653.359577
                      centerOfMass [ 3.001161 -0.000004 2.024198 ]
                      inertiaMatrix [
                        1.651197e+03 1.075366e+04 9.291994e+03
                        3.175241e-04 -3.087140e+03 -5.757440e-04
                      ]
                    }
                  }
                }
              ]
              name "link2"
              boundingObject USE link2
              physics Physics {
                density -1
                mass 14373.810297
                centerOfMass [ -0.617652 0.169249 -0.748551 ]
                inertiaMatrix [
                  1.197563e+04 2.703483e+04 3.639664e+04
                  3.906120e+02 1.550025e+03 -8.202611e+01
                ]
              }
            }
          }
          DEF base_to_kanan HingeJoint {
            jointParameters HingeJointParameters {
              axis 0.000000 1.000000 0.000000
            }
            device [
              RotationalMotor {
                name "base_to_kanan"
                maxTorque 10000
              }
              PositionSensor {
                name "base_to_kanan_sensor"
              }
            ]
            endPoint DEF kanan Solid {
              children [
                Shape {
                  appearance PBRAppearance {
                    baseColor 0.500000 0.500000 0.500000
                    roughness 1.000000
                    metalness 0
                  }
                  geometry DEF kanan Mesh {
                    url "kanan.STL"
                  }
                }
              ]
              name "kanan"
              boundingObject USE kanan
              physics Physics {
                density -1
                mass 1072.998339
                centerOfMass [ 0.137803 -1.609698 -0.780803 ]
                inertiaMatrix [
                  7.118941e+01 5.249099e+01 7.797406e+01
                  4.785389e-04 -1.899602e-01 -1.451535e-04
                ]
              }
            }
          }
          DEF base_to_kiri HingeJoint {
            jointParameters HingeJointParameters {
              axis 0.000000 1.000000 0.000000
            }
            device [
              RotationalMotor {
                name "base_to_kiri"
                maxTorque 10000
              }
              PositionSensor {
                name "base_to_kiri_sensor"
              }
            ]
            endPoint DEF kiri Solid {
              children [
                Shape {
                  appearance PBRAppearance {
                    baseColor 0.500000 0.500000 0.500000
                    roughness 1.000000
                    metalness 0
                  }
                  geometry DEF kiri Mesh {
                    url "kiri.STL"
                  }
                }
              ]
              name "kiri"
              boundingObject USE kiri
              physics Physics {
                density -1
                mass 1072.998339
                centerOfMass [ 0.137815 1.609698 -0.780803 ]
                inertiaMatrix [
                  7.118941e+01 5.249099e+01 7.797406e+01
                  4.785401e-04 -1.872236e-01 1.435644e-04
                ]
              }
            }
          }
        ]
        name "base_link"
        boundingObject USE base_link
        physics Physics {
          density -1
          mass 1992.015737
          centerOfMass [ 0.028264 -0.000082 -0.657571 ]
          inertiaMatrix [
            4.121922e+03 2.819510e+03 6.745183e+03
            -3.640462e-01 -3.328504e+00 -2.312038e-02
          ]
        }
      }
    ]
    name IS name
    physics Physics {
      density -1
      mass 1.000000
      centerOfMass [ 0.000000 0.000000 0.000000 ]
    }
  }
}
