#VRML_SIM R2023b utf8

EXTERNPROTO "https://raw.githubusercontent.com/cyberbotics/webots/R2023b/projects/objects/backgrounds/protos/TexturedBackground.proto"
EXTERNPROTO "https://raw.githubusercontent.com/cyberbotics/webots/R2023b/projects/objects/backgrounds/protos/TexturedBackgroundLight.proto"
EXTERNPROTO "https://raw.githubusercontent.com/cyberbotics/webots/R2023b/projects/objects/floors/protos/RectangleArena.proto"

WorldInfo {
  basicTimeStep 16
}
Viewpoint {
  orientation 0.08084196122705334 -0.1320901215290802 -0.9879356138430259 5.173888487262499
  position -5.058447346705302 -12.672875092476454 4.081597693781491
}
TexturedBackground {
}
TexturedBackgroundLight {
}
RectangleArena {
  floorSize 20 20
}
DEF EXCAVATOR Robot {
  translation 5.380999634214084e-06 -1.5251656161197002e-05 0.19967424238512874
  rotation 0.08834423488361984 0.9735918321660189 -0.21050947841473108 0.00015609734490093597
  children [
    DEF WHITE_UNDERCARRIAGE Pose {
      translation 0 0 0.09
      children [
        DEF BODY Shape {
          appearance PBRAppearance {
            baseColor 0.917647 0.917647 0.917647
            roughness 1
            metalness 0
          }
          geometry Box {
            size 1.7 1.7 0.3
          }
        }
      ]
    }
    DEF YELLOW_TURRET_TO_CABIN_ARM HingeJoint {
      jointParameters HingeJointParameters {
        position 8.542626668553274e-06
        axis 0 0 1
      }
      device [
        RotationalMotor {
          name "turret_motor"
        }
        PositionSensor {
          name "turret_sensor"
        }
      ]
      endPoint DEF YELLOW_TURRET_SOLID Solid {
        translation 1.999999014579051 1.4026200447928639e-05 0.29996746313036393
        rotation 4.2101097586865005e-06 -5.033511027180587e-07 0.9999999999910109 3.1416015426782633
        children [
          DEF CABIN_CAMERA Camera {
            translation 1.75 0.47 1.12
            rotation 0.2170962280351095 3.066058232766974e-07 -0.9761502075873537 -3.1415853071795863
            children [
              DEF CAMERA_POSE Pose {
                children [
                  DEF CAMERA_STICK Pose {
                    translation 0.0223154 0 -0.121423
                    rotation 0 -1 0 0.4
                    children [
                      DEF CAMERA_STICK_MATERIAL Shape {
                        appearance PBRAppearance {
                          baseColor 0.109804 0.109804 0.109804
                          roughness 1
                          metalness 0
                        }
                        geometry Cylinder {
                          height 0.17
                          radius 0.02
                        }
                      }
                    ]
                  }
                  DEF CAMERA_SHAPE Shape {
                    appearance PBRAppearance {
                      baseColor 0.917647 0.917647 0.917647
                      roughness 1
                      metalness 0
                    }
                    geometry Box {
                      size 0.1 0.2 0.1
                    }
                  }
                ]
              }
            ]
            name "cabin_camera"
            boundingObject Group {
              children [
                USE CAMERA_SHAPE
                USE CAMERA_STICK
              ]
            }
            fieldOfView 1.0472
            width 256
            height 128
            antiAliasing TRUE
            recognition Recognition {
              frameColor 0 0 1
              frameThickness 3
              segmentation TRUE
            }
          }
          DEF ARM HingeJoint {
            jointParameters HingeJointParameters {
              axis 0 0 1
              anchor 0.9 0 1
            }
            device [
              RotationalMotor {
                name "arm_connector_motor"
                minPosition -1.1
                maxPosition 1.1
              }
              PositionSensor {
                name "arm_connector_sensor"
              }
            ]
            endPoint DEF ALL_ARM_SOLID Solid {
              translation -1.3322676295501878e-15 0 -2.4424906541753444e-15
              rotation 1 0 4.707173846133103e-17 3.14159
              children [
                DEF BLUE_ARM_CONNECTOR_POSE Pose {
                  translation 0.82 0 -0.47
                  rotation 0.5802380124028778 0.5715310122167613 -0.5802380124028778 -2.1031453071795863
                  children [
                    DEF BLUE_ARM_CONNECTOR_MATERIAL Shape {
                      appearance DEF PART1_MATERIAL PBRAppearance {
                        baseColor 0.615686 0.811765 0.929412
                        roughness 1
                        metalness 0
                      }
                      geometry DEF PART1_MESH Mesh {
                        url [
                          "../protos/wheeledExcavator/part01_pin_1.stl"
                        ]
                      }
                    }
                  ]
                }
                DEF LOWER_ARM HingeJoint {
                  jointParameters HingeJointParameters {
                    axis 0 1 0
                    anchor 0.7 0 -0.5
                    minStop -0.27
                    maxStop 0.27
                  }
                  device [
                    RotationalMotor {
                      name "lower_arm_motor"
                    }
                    PositionSensor {
                      name "lower_arm_sensor"
                    }
                  ]
                  endPoint DEF LOWER_ARM_SOLID Solid {
                    translation 0.8199999999999998 0 -0.45
                    rotation -0.9364796564485361 0.2608452037189367 0.2344475053287155 1.62
                    children [
                      DEF LOWER_ARM_POSE Pose {
                        children [
                          DEF LOWER_ARM_SHAPE Shape {
                            appearance DEF LOWER_ARM_MATERIAL PBRAppearance {
                              baseColor 0.776471 0.756863 0.737255
                              roughness 1
                              metalness 0
                            }
                            geometry DEF LOWER_ARM_MESH Mesh {
                              url [
                                "../protos/WheeledExcavator/part02.stl"
                              ]
                            }
                          }
                        ]
                      }
                      DEF UPPERTOLOW HingeJoint {
                        jointParameters HingeJointParameters {
                          axis 0 0 1
                          anchor -0.84 2.35 0
                        }
                        device [
                          RotationalMotor {
                            name "uppertolow_motor"
                          }
                          PositionSensor {
                            name "uppertolow_sensor"
                          }
                        ]
                        endPoint DEF UPPERTOLOW_SOLID Solid {
                          translation -0.836322 2.3541 0
                          rotation 0 0 1 1.8326
                          children [
                            DEF SCOOP HingeJoint {
                              jointParameters HingeJointParameters {
                                axis 0 0 1
                                anchor 0.135 1.53 0
                              }
                              device [
                                RotationalMotor {
                                  name "scoop_motor"
                                }
                                PositionSensor {
                                  name "scoop_sensor"
                                }
                              ]
                              endPoint DEF SCOOP Solid {
                                children [
                                  DEF SCOOP_CONNECTOR Pose {
                                    translation -0.01 1.6 1.0195e-08
                                    rotation 0 1 0 -1.5707953071795862
                                    children [
                                      Shape {
                                        appearance PBRAppearance {
                                          baseColor 0.768627 0.886275 0.952941
                                          roughness 1
                                          metalness 0
                                        }
                                        geometry Mesh {
                                          url [
                                            "../protos/wheeledExcavator/part04.stl"
                                          ]
                                        }
                                      }
                                    ]
                                  }
                                  DEF BUCKET_MOUNT Pose {
                                    translation -0.19 1.71 2.97583e-07
                                    rotation 0.577349935856137 0.577349935856137 0.5773509358560258 -2.094395307179586
                                    children [
                                      DEF BUCKET_MOUNT_SHAPE Shape {
                                        appearance PBRAppearance {
                                          baseColor 0.498039 0.498039 0.498039
                                          roughness 1
                                          metalness 0
                                        }
                                        geometry Mesh {
                                          url [
                                            "../protos/wheeledExcavator/bucket_mount.stl"
                                          ]
                                        }
                                      }
                                    ]
                                  }
                                  DEF BUCKET_POSE Pose {
                                    translation -0.85194 1.52726 0
                                    rotation 0 0 1 -1.5707953071795862
                                    children [
                                      DEF BUCKET_SHAPE Shape {
                                        appearance DEF BUCKET_MATERIAL PBRAppearance {
                                          baseColor 0.615686 0.811765 0.929412
                                          roughness 1
                                          metalness 0
                                        }
                                        geometry DEF BUCKET Mesh {
                                          url [
                                            "../protos/WheeledExcavator/bucket.stl"
                                          ]
                                        }
                                      }
                                    ]
                                  }
                                ]
                                name "scoop"
                                boundingObject Group {
                                  children [
                                    USE BUCKET_POSE
                                    USE BUCKET_MOUNT
                                    USE SCOOP_CONNECTOR
                                  ]
                                }
                              }
                            }
                            DEF UPPERTOLOW_POSE Pose {
                              children [
                                DEF UPPERTOLOW_SHAPE Shape {
                                  appearance PBRAppearance {
                                    baseColor 0.980392 0.713725 0.003922
                                    roughness 1
                                    metalness 0
                                  }
                                  geometry Mesh {
                                    url [
                                      "../protos/wheeledExcavator/part03.stl"
                                    ]
                                  }
                                }
                              ]
                            }
                          ]
                          boundingObject USE UPPERTOLOW_SHAPE
                        }
                      }
                    ]
                    boundingObject USE LOWER_ARM_POSE
                  }
                }
              ]
              name "ARM_SOLID"
              boundingObject USE BLUE_ARM_CONNECTOR_POSE
              physics Physics {
                density -1
                mass 1
              }
            }
          }
          DEF CABIN Pose {
            translation 1.45 -0.2 0.28
            rotation -0.5773502691896258 0.5773502691896258 0.5773502691896258 -2.094395307179586
            children [
              DEF BLUE_CABIN_BODY Shape {
                appearance DEF compact_excavator_cabin_body_material PBRAppearance {
                  baseColor 0.231373 0.380392 0.705882
                  roughness 1
                  metalness 0
                }
                geometry DEF compact_excavator_cabin_body Mesh {
                  url [
                    "../protos/wheeledExcavator/compact_excavator_cabin_body.stl"
                  ]
                }
              }
            ]
          }
          DEF TURRET Pose {
            translation 2 0 0
            rotation -1 0 0 1.570796
            children [
              DEF TURRET_MATERIAL Shape {
                appearance DEF compact_excavator_turret_cabin_roller_material PBRAppearance {
                  baseColor 0.980392 0.713725 0.003922
                  roughness 1
                  metalness 0
                }
                geometry DEF compact_excavator_turret_cabin_roller Mesh {
                  url [
                    "../protos/wheeledExcavator/compact_excavator_turret_cabin_roller.stl"
                  ]
                }
              }
            ]
          }
        ]
        name "yelow_turret_solid"
        boundingObject Group {
          children [
            USE CABIN
            USE TURRET
          ]
        }
        physics Physics {
          density -1
          mass 1
        }
      }
    }
    DEF WHEEL1 HingeJoint {
      jointParameters HingeJointParameters {
        position 3.1910491150680494e-10
        axis 0 1 0
        anchor 0.85 0.9000000000000001 0
      }
      device [
        RotationalMotor {
          name "wheel1_motor"
        }
      ]
      endPoint Solid {
        translation 0.8499999927955357 0.9000000069437967 6.072752060914464e-06
        rotation -0.23314304372880978 0.9724424500041565 -5.089970746815753e-05 4.2146848510894035e-08
        children [
          DEF WHEEL Pose {
            rotation -1 0 0 1.57
            children [
              Shape {
                appearance PBRAppearance {
                  baseColor 0.980392 0.713725 0.003922
                  roughness 1
                  metalness 0
                }
                geometry Cylinder {
                  height 0.1
                  radius 0.2
                }
              }
            ]
          }
        ]
        name "wheel1"
        boundingObject USE WHEEL
        physics DEF PHYSICS_WHEEL Physics {
          density -1
          mass 0.05
        }
      }
    }
    DEF WHEEL2 HingeJoint {
      jointParameters HingeJointParameters {
        position 4.004848858339176e-10
        axis 0 1 0
        anchor 0.85 -0.9 0
      }
      device [
        RotationalMotor {
          name "wheel2_motor"
        }
      ]
      endPoint Solid {
        translation 0.8499999927071933 -0.8999999932661558 9.27211195494155e-06
        rotation -0.139182755575213 0.9902667113482982 -3.075576436658921e-05 4.2146848510894035e-08
        children [
          USE WHEEL
        ]
        name "wheel2"
        boundingObject USE WHEEL
        physics USE PHYSICS_WHEEL
      }
    }
    DEF WHEEL3 HingeJoint {
      jointParameters HingeJointParameters {
        position 7.938422124160806e-08
        axis 0 1 0
        anchor -0.85 0.9 0
      }
      device [
        RotationalMotor {
          name "wheel3_motor"
        }
      ]
      endPoint Solid {
        translation -0.8500000062701446 0.9000000065073429 2.4998850201185976e-06
        rotation -0.47136682845641015 0.8819372439382684 -0.00010385334144243972 8.940696716308595e-08
        children [
          USE WHEEL
        ]
        name "wheel3"
        boundingObject USE WHEEL
        physics USE PHYSICS_WHEEL
      }
    }
    DEF WHEEL4 HingeJoint {
      jointParameters HingeJointParameters {
        position 7.932417970601617e-08
        axis 0 1 0
        anchor -0.85 -0.9 0
      }
      device [
        RotationalMotor {
          name "wheel4_motor"
        }
      ]
      endPoint Solid {
        translation -0.8500000063601736 -0.8999999937026129 5.699244916341664e-06
        rotation -0.4713747935005441 0.8819329867060517 -0.0001049383748867602 8.940696716308595e-08
        children [
          USE WHEEL
        ]
        name "wheel4"
        boundingObject USE WHEEL
        physics USE PHYSICS_WHEEL
      }
    }
  ]
  name "wheeledExcavator"
  boundingObject USE BODY
  physics Physics {
    density -1
    mass 1
  }
  controller "obs_controller"
  supervisor TRUE
}
