#VRML_SIM R2023b utf8

EXTERNPROTO "https://raw.githubusercontent.com/cyberbotics/webots/R2023b/projects/objects/backgrounds/protos/TexturedBackground.proto"
EXTERNPROTO "https://raw.githubusercontent.com/cyberbotics/webots/R2023b/projects/objects/backgrounds/protos/TexturedBackgroundLight.proto"
EXTERNPROTO "https://raw.githubusercontent.com/cyberbotics/webots/R2023b/projects/objects/floors/protos/RectangleArena.proto"
EXTERNPROTO "https://raw.githubusercontent.com/cyberbotics/webots/R2023b/projects/objects/factory/containers/protos/WoodenBox.proto"
EXTERNPROTO "https://raw.githubusercontent.com/cyberbotics/webots/R2023b/projects/objects/factory/containers/protos/MetalStorageBox.proto"
EXTERNPROTO "https://raw.githubusercontent.com/cyberbotics/webots/R2023b/projects/objects/rocks/protos/Rock.proto"
EXTERNPROTO "https://raw.githubusercontent.com/cyberbotics/webots/R2023b/projects/objects/factory/containers/protos/PlasticFruitBox.proto"
EXTERNPROTO "https://raw.githubusercontent.com/cyberbotics/webots/R2023b/projects/objects/factory/containers/protos/CardboardBox.proto"
EXTERNPROTO "https://raw.githubusercontent.com/cyberbotics/webots/R2023b/projects/objects/balls/protos/Ball.proto"
EXTERNPROTO "https://raw.githubusercontent.com/cyberbotics/webots/R2023b/projects/objects/fruits/protos/FruitBowl.proto"
EXTERNPROTO "https://raw.githubusercontent.com/cyberbotics/webots/R2023b/projects/objects/factory/pallet/protos/WoodenPalletStack.proto"

WorldInfo {
  basicTimeStep 16
}
Viewpoint {
  orientation 0.2582849136639906 -0.4316433505872649 -0.8642759520357977 5.072036758057918
  position -11.334883091594644 -16.84556920214225 13.588177455049847
}
TexturedBackground {
}
TexturedBackgroundLight {
}
DEF FLOOR RectangleArena {
  floorSize 20 20
}
DEF EXCAVATOR Robot {
  translation -6 0 0.2
  rotation 0.08834423488361984 0.9735918321660189 -0.21050947841473108 0.00015609734490093597
  children [
    DEF WHITE_UNDERCARRIAGE Pose {
      translation 0 0 0.09
      children [
        DEF BODY Shape {
          appearance PBRAppearance {
            baseColor 0.917647 0.917647 0.917647
            roughness 1
            metalness 0
          }
          geometry Box {
            size 1.7 1.7 0.3
          }
        }
      ]
    }
    DEF YELLOW_TURRET_TO_CABIN_ARM HingeJoint {
      jointParameters HingeJointParameters {
        position 8.542626668553274e-06
        axis 0 0 1
      }
      device [
        RotationalMotor {
          name "turret_motor"
        }
        PositionSensor {
          name "turret_sensor"
        }
      ]
      endPoint DEF YELLOW_TURRET_SOLID Solid {
        translation 1.9999990145790654 1.4026200447928713e-05 0.29996746313036393
        rotation 4.2101097586865835e-06 -5.033511027180622e-07 0.999999999991011 3.1416015426782633
        children [
          DEF SEGMENTED_IMAGE_DISPLAY Display {
            name "segmented_image_display"
            width 256
            height 128
          }
          DEF CABIN_CAMERA Camera {
            translation 1.33 0.46 0.93
            rotation -0.11960298072285644 0.009999636485096178 0.992771441104333 -2.925
            children [
              DEF CAMERA_POSE Pose {
                children [
                  DEF CAMERA_STICK Pose {
                    translation 0.013 0 -0.121423
                    rotation 0 -1 0 0.1382003061004253
                    children [
                      DEF CAMERA_STICK_MATERIAL Shape {
                        appearance PBRAppearance {
                          baseColor 0.109804 0.109804 0.109804
                          roughness 1
                          metalness 0
                        }
                        geometry Cylinder {
                          height 0.17
                          radius 0.02
                        }
                      }
                    ]
                  }
                  DEF CAMERA_SHAPE Shape {
                    appearance PBRAppearance {
                      baseColor 0.917647 0.917647 0.917647
                      roughness 1
                      metalness 0
                    }
                    geometry Box {
                      size 0.1 0.2 0.1
                    }
                  }
                ]
              }
            ]
            name "cabin_camera"
            boundingObject Group {
              children [
                USE CAMERA_SHAPE
                USE CAMERA_STICK
              ]
            }
            fieldOfView 1.1
            width 256
            height 128
            antiAliasing TRUE
            recognition Recognition {
              frameColor 0 0.333333 1
              frameThickness 2
              segmentation TRUE
            }
          }
          DEF ARM HingeJoint {
            jointParameters HingeJointParameters {
              axis 0 0 1
              anchor 0.9 0 1
            }
            device [
              RotationalMotor {
                name "arm_connector_motor"
                minPosition -1.1
                maxPosition 1.1
              }
              PositionSensor {
                name "arm_connector_sensor"
              }
            ]
            endPoint DEF ALL_ARM_SOLID Solid {
              translation -1.3322676295501878e-15 0 -2.4424906541753444e-15
              rotation 1 0 4.707173846133103e-17 3.14159
              children [
                DEF BLUE_ARM_CONNECTOR_POSE Pose {
                  translation 0.82 0 -0.47
                  rotation 0.5802380124028778 0.5715310122167613 -0.5802380124028778 -2.1031453071795863
                  children [
                    DEF BLUE_ARM_CONNECTOR_MATERIAL Shape {
                      appearance DEF PART1_MATERIAL PBRAppearance {
                        baseColor 0.615686 0.811765 0.929412
                        roughness 1
                        metalness 0
                      }
                      geometry DEF PART1_MESH Mesh {
                        url [
                          "../assets/wheeledExcavator/part01_pin_1.stl"
                        ]
                      }
                    }
                  ]
                }
                DEF LOWER_ARM HingeJoint {
                  jointParameters HingeJointParameters {
                    position -0.1
                    axis 0 1 0
                    anchor 0.7 0 -0.5
                    minStop -0.27
                    maxStop 0.27
                  }
                  device [
                    RotationalMotor {
                      name "lower_arm_motor"
                    }
                    PositionSensor {
                      name "lower_arm_sensor"
                    }
                  ]
                  endPoint DEF LOWER_ARM_SOLID Solid {
                    translation 0.8144088290010215 0 -0.43826978173847936
                    rotation -0.9579603645335718 0.215399062971302 0.18951301710909216 1.5961700619693866
                    children [
                      DEF LOWER_ARM_POSE Pose {
                        children [
                          DEF LOWER_ARM_SHAPE Shape {
                            appearance DEF LOWER_ARM_MATERIAL PBRAppearance {
                              baseColor 0.776471 0.756863 0.737255
                              roughness 1
                              metalness 0
                            }
                            geometry DEF LOWER_ARM_MESH Mesh {
                              url [
                                "../assets/wheeledExcavator/part02.stl"
                              ]
                            }
                          }
                        ]
                      }
                      DEF UPPERTOLOW HingeJoint {
                        jointParameters HingeJointParameters {
                          position 0.2
                          axis 0 0 1
                          anchor -0.84 2.35 0
                        }
                        device [
                          RotationalMotor {
                            name "uppertolow_motor"
                          }
                          PositionSensor {
                            name "uppertolow_sensor"
                          }
                        ]
                        endPoint DEF UPPERTOLOW_SOLID Solid {
                          translation -0.8372098593829597 2.3547489787678133 0
                          rotation 0 0 1 2.0326
                          children [
                            DEF SCOOP HingeJoint {
                              jointParameters HingeJointParameters {
                                axis 0 0 1
                                anchor 0.135 1.53 0
                              }
                              device [
                                RotationalMotor {
                                  name "scoop_motor"
                                }
                                PositionSensor {
                                  name "scoop_sensor"
                                }
                              ]
                              endPoint DEF SCOOP Solid {
                                children [
                                  DEF SCOOP_CONNECTOR Pose {
                                    translation -0.01 1.6 1.0195e-08
                                    rotation 0 1 0 -1.5707953071795862
                                    children [
                                      Shape {
                                        appearance PBRAppearance {
                                          baseColor 0.768627 0.886275 0.952941
                                          roughness 1
                                          metalness 0
                                        }
                                        geometry Mesh {
                                          url [
                                            "../assets/wheeledExcavator/part04.stl"
                                          ]
                                        }
                                      }
                                    ]
                                  }
                                  DEF BUCKET_MOUNT Pose {
                                    translation -0.19 1.71 2.97583e-07
                                    rotation 0.577349935856137 0.577349935856137 0.5773509358560258 -2.094395307179586
                                    children [
                                      DEF BUCKET_MOUNT_SHAPE Shape {
                                        appearance PBRAppearance {
                                          baseColor 0.498039 0.498039 0.498039
                                          roughness 1
                                          metalness 0
                                        }
                                        geometry Mesh {
                                          url [
                                            "../assets/wheeledExcavator/bucket_mount.stl"
                                          ]
                                        }
                                      }
                                    ]
                                  }
                                  DEF BUCKET_POSE Pose {
                                    translation -0.85194 1.52726 0
                                    rotation 0 0 1 -1.5707953071795862
                                    children [
                                      DEF BUCKET_SHAPE Shape {
                                        appearance DEF BUCKET_MATERIAL PBRAppearance {
                                          baseColor 0.615686 0.811765 0.929412
                                          roughness 1
                                          metalness 0
                                        }
                                        geometry DEF BUCKET Mesh {
                                          url [
                                            "../assets/wheeledExcavator/bucket.stl"
                                          ]
                                        }
                                      }
                                    ]
                                  }
                                ]
                                name "scoop"
                                boundingObject Group {
                                  children [
                                    USE BUCKET_POSE
                                    USE BUCKET_MOUNT
                                    USE SCOOP_CONNECTOR
                                  ]
                                }
                              }
                            }
                            DEF UPPERTOLOW_POSE Pose {
                              children [
                                DEF UPPERTOLOW_SHAPE Shape {
                                  appearance PBRAppearance {
                                    baseColor 0.980392 0.713725 0.003922
                                    roughness 1
                                    metalness 0
                                  }
                                  geometry Mesh {
                                    url [
                                      "../assets/wheeledExcavator/part03.stl"
                                    ]
                                  }
                                }
                              ]
                            }
                          ]
                          boundingObject USE UPPERTOLOW_SHAPE
                        }
                      }
                    ]
                    boundingObject USE LOWER_ARM_POSE
                  }
                }
              ]
              name "ARM_SOLID"
              boundingObject USE BLUE_ARM_CONNECTOR_POSE
              physics Physics {
                density -1
                mass 1
              }
            }
          }
          DEF CABIN Pose {
            translation 1.45 -0.2 0.28
            rotation -0.5773502691896258 0.5773502691896258 0.5773502691896258 -2.094395307179586
            children [
              DEF BLUE_CABIN_BODY Shape {
                appearance DEF compact_excavator_cabin_body_material PBRAppearance {
                  baseColor 0.231373 0.380392 0.705882
                  roughness 1
                  metalness 0
                }
                geometry DEF compact_excavator_cabin_body Mesh {
                  url [
                    "../assets/wheeledExcavator/compact_excavator_cabin_body.stl"
                  ]
                }
              }
            ]
          }
          DEF TURRET Pose {
            translation 2 0 0
            rotation -1 0 0 1.570796
            children [
              DEF TURRET_MATERIAL Shape {
                appearance DEF compact_excavator_turret_cabin_roller_material PBRAppearance {
                  baseColor 0.980392 0.713725 0.003922
                  roughness 1
                  metalness 0
                }
                geometry DEF compact_excavator_turret_cabin_roller Mesh {
                  url [
                    "../assets/wheeledExcavator/compact_excavator_turret_cabin_roller.stl"
                  ]
                }
              }
            ]
          }
        ]
        name "yelow_turret_solid"
        boundingObject Group {
          children [
            USE CABIN
            USE TURRET
          ]
        }
        physics Physics {
          density -1
          mass 1
        }
      }
    }
    DEF WHEEL1 HingeJoint {
      jointParameters HingeJointParameters {
        position 3.1910491150680494e-10
        axis 0 1 0
        anchor 0.85 0.9000000000000001 0
      }
      device [
        RotationalMotor {
          name "wheel1_motor"
        }
      ]
      endPoint Solid {
        translation 0.8499999927957301 0.9000000069437967 6.0727520611512455e-06
        rotation -0.10756920741806994 0.9941975986010082 -2.3482686659249395e-05 4.2146848510894035e-08
        children [
          DEF WHEEL Pose {
            rotation -1 0 0 1.57
            children [
              Shape {
                appearance PBRAppearance {
                  baseColor 0.980392 0.713725 0.003922
                  roughness 1
                  metalness 0
                }
                geometry Cylinder {
                  height 0.1
                  radius 0.2
                }
              }
            ]
          }
        ]
        name "wheel1"
        boundingObject USE WHEEL
        physics DEF PHYSICS_WHEEL Physics {
          density -1
          mass 0.05
        }
      }
    }
    DEF WHEEL2 HingeJoint {
      jointParameters HingeJointParameters {
        position 4.004848858339176e-10
        axis 0 1 0
        anchor 0.85 -0.9 0
      }
      device [
        RotationalMotor {
          name "wheel2_motor"
        }
      ]
      endPoint Solid {
        translation 0.8499999927075707 -0.8999999932661558 9.272111955242369e-06
        rotation -0.05226917216754827 0.998633032453633 -1.1549037331654675e-05 4.2146848510894035e-08
        children [
          USE WHEEL
        ]
        name "wheel2"
        boundingObject USE WHEEL
        physics USE PHYSICS_WHEEL
      }
    }
    DEF WHEEL3 HingeJoint {
      jointParameters HingeJointParameters {
        position 7.938422124160806e-08
        axis 0 1 0
        anchor -0.85 0.9 0
      }
      device [
        RotationalMotor {
          name "wheel3_motor"
        }
      ]
      endPoint Solid {
        translation -0.8500000062701446 0.9000000065073429 2.499885020118625e-06
        rotation -0.47136682845641015 0.8819372439382684 -0.0001038533414424409 8.940696716308595e-08
        children [
          USE WHEEL
        ]
        name "wheel3"
        boundingObject USE WHEEL
        physics USE PHYSICS_WHEEL
      }
    }
    DEF WHEEL4 HingeJoint {
      jointParameters HingeJointParameters {
        position 7.932417970601617e-08
        axis 0 1 0
        anchor -0.85 -0.9 0
      }
      device [
        RotationalMotor {
          name "wheel4_motor"
        }
      ]
      endPoint Solid {
        translation -0.8500000063601736 -0.8999999937026129 5.699244916341664e-06
        rotation -0.4713747935005441 0.8819329867060517 -0.00010493837488675902 8.940696716308595e-08
        children [
          USE WHEEL
        ]
        name "wheel4"
        boundingObject USE WHEEL
        physics USE PHYSICS_WHEEL
      }
    }
  ]
  name "wheeledExcavator"
  boundingObject USE BODY
  physics Physics {
    density -1
    mass 1
  }
  controller "conventional_color_control"
  supervisor TRUE
}
DEF WOODEN_BOX WoodenBox {
  translation 3.57932 2.68803 0.3
  rotation 0 0 1 0.261799
}
DEF STORAGE_BOX MetalStorageBox {
  translation 1.57868 4.45764 5.32907e-15
}
DEF BIG_ROCK Rock {
  translation -1.65723 -3.82758 -1.23457e-13
  scale 6
}
DEF SMALL_ROCK Rock {
  translation -1.70572 -3.31039 -2.90434e-13
  name "rock(7)"
  scale 4
}
DEF FRUIT_BOX PlasticFruitBox {
  translation -1.15082 3.44705 -7.10543e-15
  rotation 0 0 1 0.523599
}
DEF CARDBOARD CardboardBox {
  translation 1.48817 -4.21395 0.3
}
DEF TARGET Ball {
  translation 3.76374 -2.46302 0.393653
  color 1 0 0
  radius 0.4
}
DEF FRUIT_BALL FruitBowl {
  translation 0.573823 2.35458 0
  rotation 0 0 1 0.785398
  name "fruit_bowl"
}
DEF WOODEN_PALLET_STACK WoodenPalletStack {
  translation 6.01173 0.757877 6.39488e-14
  rotation 0 0 1 2.0944
}
