#VRML_SIM R2023b utf8

EXTERNPROTO "https://raw.githubusercontent.com/cyberbotics/webots/R2023b/projects/objects/backgrounds/protos/TexturedBackground.proto"
EXTERNPROTO "https://raw.githubusercontent.com/cyberbotics/webots/R2023b/projects/objects/backgrounds/protos/TexturedBackgroundLight.proto"
EXTERNPROTO "https://raw.githubusercontent.com/cyberbotics/webots/R2023b/projects/objects/floors/protos/RectangleArena.proto"

WorldInfo {
  basicTimeStep 16
}
Viewpoint {
  orientation 0.1670084467271549 -0.24001899662318152 -0.9562944420949984 5.025129141955908
  position -3.9495345825074244 -16.027736978688875 6.809181439408849
}
TexturedBackground {
}
TexturedBackgroundLight {
}
RectangleArena {
  floorSize 20 20
}
DEF EXCAVATOR Robot {
  translation 0 0 0.204728
  children [
    DEF WHITE_UNDERCARRIAGE Pose {
      translation 0 0 0.09
      children [
        DEF BODY Shape {
          appearance PBRAppearance {
            baseColor 0.917647 0.917647 0.917647
            roughness 1
            metalness 0
          }
          geometry Box {
            size 1.7 1.7 0.3
          }
        }
      ]
    }
    DEF CABIN_TURRET_ARM HingeJoint {
      jointParameters HingeJointParameters {
        axis 0 0 1
      }
      device [
        RotationalMotor {
          name "turret_motor"
        }
        PositionSensor {
          name "turret_sensor"
        }
      ]
      endPoint DEF TURRET_SOLID Solid {
        translation 1.999999014625853 -3.0590444713984866e-06 0.29996746313036393
        rotation 4.2101076086360466e-06 -5.033690854064426e-07 0.999999999991011 3.141593000051595
        children [
          DEF ARM HingeJoint {
            jointParameters HingeJointParameters {
              axis 0 0 -1
            }
            device [
              RotationalMotor {
                name "arm_rotation_motor"
              }
              PositionSensor {
                name "arm_rotation_sensor"
              }
            ]
            endPoint DEF ARM_SOLID Solid {
              rotation 1 0 1.9750552711854814e-23 3.14159
              children [
                DEF ARM_CONNECTOR_POSE Pose {
                  translation 0.82 0 -0.47
                  rotation 0.5802380124028778 0.5715310122167613 -0.5802380124028778 -2.1031453071795863
                  children [
                    Shape {
                      appearance DEF PART1_MATERIAL PBRAppearance {
                        baseColor 0.615686 0.811765 0.929412
                        roughness 1
                        metalness 0
                      }
                      geometry DEF PART1_MESH Mesh {
                        url [
                          "../protos/wheeledExcavator/part01_pin_1.stl"
                        ]
                      }
                      castShadows FALSE
                    }
                  ]
                }
                DEF LOWER_ARM HingeJoint {
                  jointParameters HingeJointParameters {
                  }
                  device [
                    RotationalMotor {
                      name "lower_arm_motor"
                    }
                    PositionSensor {
                      name "lower_arm_sensor"
                    }
                  ]
                  endPoint DEF LOWER_ARM_SOLID Solid {
                    translation 0.82 0 -0.45
                    rotation -0.9364796564485361 0.2608452037189367 0.2344475053287155 1.62
                    children [
                      DEF LOWER_ARM_POSE Pose {
                        children [
                          Shape {
                            appearance DEF PART2_MATERIAL PBRAppearance {
                              baseColor 0.776471 0.756863 0.737255
                              roughness 1
                              metalness 0
                            }
                            geometry DEF PART2_MESH Mesh {
                              url [
                                "../protos/WheeledExcavator/part02.stl"
                              ]
                            }
                          }
                        ]
                      }
                      DEF UPPERTOLOW HingeJoint {
                        jointParameters HingeJointParameters {
                        }
                        device [
                          RotationalMotor {
                            name "uppertolow_motor"
                          }
                          PositionSensor {
                            name "uppertolow_sensor"
                          }
                        ]
                        endPoint DEF UPPERTOLOW_SOLID Solid {
                          translation -0.836322 2.3541 0
                          rotation 0 0 1 1.8326
                          children [
                            DEF SCOOP HingeJoint {
                              jointParameters HingeJointParameters {
                              }
                              device [
                                RotationalMotor {
                                  name "scoop_motor"
                                }
                                PositionSensor {
                                  name "scoop_sensor"
                                }
                              ]
                              endPoint DEF SCOOP Solid {
                                children [
                                  DEF SCOOP_CONNECTOR Pose {
                                    translation -0.01 1.6 1.0195e-08
                                    rotation 0 1 0 -1.5707953071795862
                                    children [
                                      Shape {
                                        appearance PBRAppearance {
                                          baseColor 0.768627 0.886275 0.952941
                                          roughness 1
                                          metalness 0
                                        }
                                        geometry Mesh {
                                          url [
                                            "../protos/wheeledExcavator/part04.stl"
                                          ]
                                        }
                                      }
                                    ]
                                  }
                                  DEF BUCKET_MOUNT Pose {
                                    translation -0.19 1.71 2.97583e-07
                                    rotation 0.577349935856137 0.577349935856137 0.5773509358560258 -2.094395307179586
                                    children [
                                      DEF BUCKET_MOUNT_SHAPE Shape {
                                        appearance PBRAppearance {
                                          baseColor 0.498039 0.498039 0.498039
                                          roughness 1
                                          metalness 0
                                        }
                                        geometry Mesh {
                                          url [
                                            "../protos/wheeledExcavator/bucket_mount.stl"
                                          ]
                                        }
                                      }
                                    ]
                                  }
                                  DEF BUCKET_POSE Pose {
                                    translation -0.85194 1.52726 0
                                    rotation 0 0 1 -1.5707953071795862
                                    children [
                                      DEF BUCKET_SHAPE Shape {
                                        appearance DEF BUCKET_MATERIAL PBRAppearance {
                                          baseColor 0.615686 0.811765 0.929412
                                          roughness 1
                                          metalness 0
                                        }
                                        geometry DEF BUCKET Mesh {
                                          url [
                                            "../protos/WheeledExcavator/bucket.stl"
                                          ]
                                        }
                                      }
                                    ]
                                  }
                                ]
                                name "scoop"
                                boundingObject Group {
                                  children [
                                    USE BUCKET_POSE
                                    USE BUCKET_MOUNT
                                    USE SCOOP_CONNECTOR
                                  ]
                                }
                              }
                            }
                            DEF UPPERTOLOW_POSE Pose {
                              children [
                                DEF UPPERTOLOW_SHAPE Shape {
                                  appearance PBRAppearance {
                                    baseColor 0.980392 0.713725 0.003922
                                    roughness 1
                                    metalness 0
                                  }
                                  geometry Mesh {
                                    url [
                                      "../protos/wheeledExcavator/part03.stl"
                                    ]
                                  }
                                  castShadows FALSE
                                }
                              ]
                            }
                          ]
                          boundingObject USE UPPERTOLOW_SHAPE
                        }
                      }
                    ]
                    boundingObject USE LOWER_ARM_POSE
                  }
                }
              ]
              name "ARM_SOLID"
              boundingObject USE ARM_CONNECTOR_POSE
              physics Physics {
                density -1
                mass 1
              }
            }
          }
          DEF CABIN Pose {
            translation 1.45 -0.2 0.28
            rotation -0.5773502691896258 0.5773502691896258 0.5773502691896258 -2.094395307179586
            children [
              DEF BLUE_CABIN_BODY Shape {
                appearance DEF compact_excavator_cabin_body_material PBRAppearance {
                  baseColor 0.231373 0.380392 0.705882
                  roughness 1
                  metalness 0
                }
                geometry DEF compact_excavator_cabin_body Mesh {
                  url [
                    "../protos/wheeledExcavator/compact_excavator_cabin_body.stl"
                  ]
                }
                castShadows FALSE
              }
            ]
          }
          DEF TURRET Pose {
            translation 2 0 0
            rotation -1 0 0 1.570796
            children [
              Shape {
                appearance DEF compact_excavator_turret_cabin_roller_material PBRAppearance {
                  baseColor 0.980392 0.713725 0.003922
                  roughness 1
                  metalness 0
                }
                geometry DEF compact_excavator_turret_cabin_roller Mesh {
                  url [
                    "../protos/wheeledExcavator/compact_excavator_turret_cabin_roller.stl"
                  ]
                }
              }
            ]
          }
        ]
        name "yelow_turret_solid"
        boundingObject Group {
          children [
            USE CABIN
            USE TURRET
          ]
        }
        physics Physics {
          density -1
          mass 1
        }
      }
    }
    DEF WHEEL1 HingeJoint {
      jointParameters HingeJointParameters {
        position 3.944715691954095e-08
        axis 0 1 0
        anchor 0.85 0.9000000000000001 0
      }
      device [
        RotationalMotor {
          name "wheel1_motor"
        }
      ]
      endPoint Solid {
        translation 0.8499999927952582 0.9000000069437967 6.0727520605688214e-06
        rotation -0.7040307237122114 0.7101694983869883 -0.0001537206328386868 5.960464477539063e-08
        children [
          DEF WHEEL Pose {
            rotation -1 0 0 1.57
            children [
              Shape {
                appearance PBRAppearance {
                  baseColor 0.980392 0.713725 0.003922
                  roughness 1
                  metalness 0
                }
                geometry Cylinder {
                  height 0.1
                  radius 0.2
                }
              }
            ]
          }
        ]
        name "wheel1"
        boundingObject USE WHEEL
        physics DEF PHYSICS_WHEEL Physics {
          density -1
          mass 0.05
        }
      }
    }
    DEF WHEEL2 HingeJoint {
      jointParameters HingeJointParameters {
        position 3.946096151677051e-08
        axis 0 1 0
        anchor 0.85 -0.9 0
      }
      device [
        RotationalMotor {
          name "wheel2_motor"
        }
      ]
      endPoint Solid {
        translation 0.8499999927065554 -0.8999999932661558 9.272111954429248e-06
        rotation -0.7022670486219306 0.7119135961129727 -0.0001552074040352037 5.960464477539063e-08
        children [
          USE WHEEL
        ]
        name "wheel2"
        boundingObject USE WHEEL
        physics USE PHYSICS_WHEEL
      }
    }
    DEF WHEEL3 HingeJoint {
      jointParameters HingeJointParameters {
        position 3.9447147755276025e-08
        axis 0 1 0
        anchor -0.85 0.9 0
      }
      device [
        RotationalMotor {
          name "wheel3_motor"
        }
      ]
      endPoint Solid {
        translation -0.8500000062702444 0.9000000065073429 2.499885019868117e-06
        rotation -0.7076574944852349 0.706555621437802 -0.0001559279350869497 5.960464477539063e-08
        children [
          USE WHEEL
        ]
        name "wheel3"
        boundingObject USE WHEEL
        physics USE PHYSICS_WHEEL
      }
    }
    DEF WHEEL4 HingeJoint {
      jointParameters HingeJointParameters {
        position 3.946095245408605e-08
        axis 0 1 0
        anchor -0.85 -0.9 0
      }
      device [
        RotationalMotor {
          name "wheel4_motor"
        }
      ]
      endPoint Solid {
        translation -0.8500000063604007 -0.8999999937026129 5.699244916088182e-06
        rotation -0.7073784795844894 0.7068349608055495 -0.0001574920744730615 5.960464477539063e-08
        children [
          USE WHEEL
        ]
        name "wheel4"
        boundingObject USE WHEEL
        physics USE PHYSICS_WHEEL
      }
    }
  ]
  name "wheeledExcavator"
  boundingObject USE BODY
  physics Physics {
    density -1
    mass 1
  }
  controller "obs_controller"
  supervisor TRUE
}
